{
 "cells": [
  {
   "cell_type": "code",
   "execution_count": 1,
   "metadata": {
    "pycharm": {
     "name": "#%%\n"
    }
   },
   "outputs": [],
   "source": [
    "import sys, os\n",
    "sys.path.insert(0, '..')"
   ]
  },
  {
   "cell_type": "code",
   "execution_count": 2,
   "metadata": {
    "pycharm": {
     "name": "#%%\n"
    }
   },
   "outputs": [
    {
     "name": "stderr",
     "output_type": "stream",
     "text": [
      "\n",
      "Bad key \"text.kerning_factor\" on line 4 in\n",
      "/home/ashutosh/miniconda3/envs/study/lib/python3.7/site-packages/matplotlib/mpl-data/stylelib/_classic_test_patch.mplstyle.\n",
      "You probably need to get an updated matplotlibrc file from\n",
      "http://github.com/matplotlib/matplotlib/blob/master/matplotlibrc.template\n",
      "or from the matplotlib source distribution\n",
      "2022-08-17 12:43:25.247236: I tensorflow/core/platform/cpu_feature_guard.cc:142] Your CPU supports instructions that this TensorFlow binary was not compiled to use: SSE4.1 SSE4.2 AVX AVX2 AVX512F FMA\n",
      "2022-08-17 12:43:25.268655: I tensorflow/core/platform/profile_utils/cpu_utils.cc:94] CPU Frequency: 2304000000 Hz\n",
      "2022-08-17 12:43:25.269417: I tensorflow/compiler/xla/service/service.cc:168] XLA service 0x5600b5e62e00 initialized for platform Host (this does not guarantee that XLA will be used). Devices:\n",
      "2022-08-17 12:43:25.269443: I tensorflow/compiler/xla/service/service.cc:176]   StreamExecutor device (0): Host, Default Version\n",
      "2022-08-17 12:43:25.269594: I tensorflow/core/common_runtime/process_util.cc:147] Creating new thread pool with default inter op setting: 2. Tune using inter_op_parallelism_threads for best performance.\n"
     ]
    }
   ],
   "source": [
    "import graph_tool.all as gt\n",
    "import graph_embeddings\n",
    "from models.crosswalk import Crosswalk\n",
    "from utils.score import statistical_parity\n",
    "import faiss\n",
    "import residual2vec as rv\n",
    "import numpy as np\n",
    "import pandas as pd\n",
    "from scipy import sparse\n",
    "import seaborn as sns\n",
    "import matplotlib.pyplot as plt\n",
    "from tqdm import tqdm\n",
    "import networkx as nx\n",
    "import warnings\n",
    "warnings.filterwarnings(\"ignore\")\n",
    "\n",
    "from sklearn.neighbors import kneighbors_graph\n",
    "from sklearn.discriminant_analysis import LinearDiscriminantAnalysis\n",
    "from sklearn.decomposition import PCA\n",
    "from sklearn.preprocessing import LabelEncoder\n",
    "\n",
    "from utils import node_classification"
   ]
  },
  {
   "cell_type": "code",
   "execution_count": 3,
   "metadata": {},
   "outputs": [],
   "source": [
    "models = {}\n",
    "window_length = 5\n",
    "num_walks = 10\n",
    "dim = 128"
   ]
  },
  {
   "cell_type": "code",
   "execution_count": 4,
   "metadata": {},
   "outputs": [],
   "source": [
    "DATA_FILE = '../data/polbooks.gml'\n",
    "G = nx.read_gml(DATA_FILE)\n",
    "G = nx.relabel.convert_node_labels_to_integers(G, first_label=0, ordering='default')\n",
    "\n",
    "nodes = G.nodes(data=True)\n",
    "labels, group_ids = np.unique([n[1]['value'] for n in nodes], return_inverse=True)\n",
    "\n",
    "A = nx.adjacency_matrix(G).asfptype()\n",
    "deg = np.array(A.sum(axis=1)).reshape(-1)\n",
    "G = nx.from_scipy_sparse_matrix(A)"
   ]
  },
  {
   "cell_type": "code",
   "execution_count": 5,
   "metadata": {
    "pycharm": {
     "name": "#%%\n"
    }
   },
   "outputs": [],
   "source": [
    "models[\"degree-unbiased\"] = rv.residual2vec_sgd(\n",
    "    noise_sampler=rv.ConfigModelNodeSampler(),\n",
    "    window_length=window_length,\n",
    "    num_walks=num_walks,\n",
    "    cuda=True,\n",
    "    walk_length=80\n",
    ")\n",
    "\n",
    "models[\"group-unbiased\"] = rv.residual2vec_sgd(\n",
    "    noise_sampler=rv.SBMNodeSampler(\n",
    "        group_membership=group_ids, window_length=window_length,\n",
    "    ),\n",
    "    window_length=window_length,\n",
    "    num_walks=num_walks,\n",
    "    cuda=True,\n",
    "    walk_length=80,\n",
    ")\n"
   ]
  },
  {
   "cell_type": "code",
   "execution_count": null,
   "metadata": {},
   "outputs": [
    {
     "name": "stderr",
     "output_type": "stream",
     "text": [
      "ERROR:root:Internal Python error in the inspect module.\n",
      "Below is the traceback from this internal error.\n",
      "\n",
      "ERROR:root:Internal Python error in the inspect module.\n",
      "Below is the traceback from this internal error.\n",
      "\n",
      "ERROR:root:Internal Python error in the inspect module.\n",
      "Below is the traceback from this internal error.\n",
      "\n"
     ]
    },
    {
     "name": "stdout",
     "output_type": "stream",
     "text": [
      "Traceback (most recent call last):\n",
      "  File \"/home/ashutosh/miniconda3/envs/study/lib/python3.7/site-packages/IPython/core/interactiveshell.py\", line 3457, in run_code\n",
      "    exec(code_obj, self.user_global_ns, self.user_ns)\n",
      "  File \"/tmp/ipykernel_15621/2869884725.py\", line 4, in <module>\n",
      "    emb = model.fit(A).transform(m)\n",
      "NameError: name 'model' is not defined\n",
      "\n",
      "During handling of the above exception, another exception occurred:\n",
      "\n",
      "Traceback (most recent call last):\n",
      "  File \"/home/ashutosh/miniconda3/envs/study/lib/python3.7/site-packages/IPython/core/interactiveshell.py\", line 2077, in showtraceback\n",
      "    stb = value._render_traceback_()\n",
      "AttributeError: 'NameError' object has no attribute '_render_traceback_'\n",
      "\n",
      "During handling of the above exception, another exception occurred:\n",
      "\n",
      "Traceback (most recent call last):\n",
      "  File \"/home/ashutosh/miniconda3/envs/study/lib/python3.7/site-packages/IPython/core/ultratb.py\", line 1101, in get_records\n",
      "    return _fixed_getinnerframes(etb, number_of_lines_of_context, tb_offset)\n",
      "  File \"/home/ashutosh/miniconda3/envs/study/lib/python3.7/site-packages/IPython/core/ultratb.py\", line 248, in wrapped\n",
      "    return f(*args, **kwargs)\n",
      "  File \"/home/ashutosh/miniconda3/envs/study/lib/python3.7/site-packages/IPython/core/ultratb.py\", line 281, in _fixed_getinnerframes\n",
      "    records = fix_frame_records_filenames(inspect.getinnerframes(etb, context))\n",
      "  File \"/home/ashutosh/miniconda3/envs/study/lib/python3.7/inspect.py\", line 1502, in getinnerframes\n",
      "    frameinfo = (tb.tb_frame,) + getframeinfo(tb, context)\n",
      "  File \"/home/ashutosh/miniconda3/envs/study/lib/python3.7/inspect.py\", line 1460, in getframeinfo\n",
      "    filename = getsourcefile(frame) or getfile(frame)\n",
      "  File \"/home/ashutosh/miniconda3/envs/study/lib/python3.7/inspect.py\", line 696, in getsourcefile\n",
      "    if getattr(getmodule(object, filename), '__loader__', None) is not None:\n",
      "  File \"/home/ashutosh/miniconda3/envs/study/lib/python3.7/inspect.py\", line 733, in getmodule\n",
      "    if ismodule(module) and hasattr(module, '__file__'):\n",
      "  File \"/home/ashutosh/miniconda3/envs/study/lib/python3.7/site-packages/tensorflow/__init__.py\", line 50, in __getattr__\n",
      "    module = self._load()\n",
      "  File \"/home/ashutosh/miniconda3/envs/study/lib/python3.7/site-packages/tensorflow/__init__.py\", line 44, in _load\n",
      "    module = _importlib.import_module(self.__name__)\n",
      "  File \"/home/ashutosh/miniconda3/envs/study/lib/python3.7/importlib/__init__.py\", line 127, in import_module\n",
      "    return _bootstrap._gcd_import(name[level:], package, level)\n",
      "  File \"<frozen importlib._bootstrap>\", line 1006, in _gcd_import\n",
      "  File \"<frozen importlib._bootstrap>\", line 983, in _find_and_load\n",
      "  File \"<frozen importlib._bootstrap>\", line 965, in _find_and_load_unlocked\n",
      "ModuleNotFoundError: No module named 'tensorflow_core.estimator'\n",
      "Traceback (most recent call last):\n",
      "  File \"/home/ashutosh/miniconda3/envs/study/lib/python3.7/site-packages/IPython/core/interactiveshell.py\", line 3457, in run_code\n",
      "    exec(code_obj, self.user_global_ns, self.user_ns)\n",
      "  File \"/tmp/ipykernel_15621/2869884725.py\", line 4, in <module>\n",
      "    emb = model.fit(A).transform(m)\n",
      "NameError: name 'model' is not defined\n",
      "\n",
      "During handling of the above exception, another exception occurred:\n",
      "\n",
      "Traceback (most recent call last):\n",
      "  File \"/home/ashutosh/miniconda3/envs/study/lib/python3.7/site-packages/IPython/core/interactiveshell.py\", line 2077, in showtraceback\n",
      "    stb = value._render_traceback_()\n",
      "AttributeError: 'NameError' object has no attribute '_render_traceback_'\n",
      "\n",
      "During handling of the above exception, another exception occurred:\n",
      "\n",
      "Traceback (most recent call last):\n",
      "  File \"/home/ashutosh/miniconda3/envs/study/lib/python3.7/site-packages/IPython/core/interactiveshell.py\", line 3377, in run_ast_nodes\n",
      "    if (await self.run_code(code, result,  async_=asy)):\n",
      "  File \"/home/ashutosh/miniconda3/envs/study/lib/python3.7/site-packages/IPython/core/interactiveshell.py\", line 3474, in run_code\n",
      "    self.showtraceback(running_compiled_code=True)\n",
      "  File \"/home/ashutosh/miniconda3/envs/study/lib/python3.7/site-packages/IPython/core/interactiveshell.py\", line 2080, in showtraceback\n",
      "    value, tb, tb_offset=tb_offset)\n",
      "  File \"/home/ashutosh/miniconda3/envs/study/lib/python3.7/site-packages/IPython/core/ultratb.py\", line 1368, in structured_traceback\n",
      "    self, etype, value, tb, tb_offset, number_of_lines_of_context)\n",
      "  File \"/home/ashutosh/miniconda3/envs/study/lib/python3.7/site-packages/IPython/core/ultratb.py\", line 1268, in structured_traceback\n",
      "    self, etype, value, tb, tb_offset, number_of_lines_of_context\n",
      "  File \"/home/ashutosh/miniconda3/envs/study/lib/python3.7/site-packages/IPython/core/ultratb.py\", line 1125, in structured_traceback\n",
      "    tb_offset)\n",
      "  File \"/home/ashutosh/miniconda3/envs/study/lib/python3.7/site-packages/IPython/core/ultratb.py\", line 1082, in format_exception_as_a_whole\n",
      "    last_unique, recursion_repeat = find_recursion(orig_etype, evalue, records)\n",
      "  File \"/home/ashutosh/miniconda3/envs/study/lib/python3.7/site-packages/IPython/core/ultratb.py\", line 382, in find_recursion\n",
      "    return len(records), 0\n",
      "TypeError: object of type 'NoneType' has no len()\n",
      "\n",
      "During handling of the above exception, another exception occurred:\n",
      "\n",
      "Traceback (most recent call last):\n",
      "  File \"/home/ashutosh/miniconda3/envs/study/lib/python3.7/site-packages/IPython/core/interactiveshell.py\", line 2077, in showtraceback\n",
      "    stb = value._render_traceback_()\n",
      "AttributeError: 'TypeError' object has no attribute '_render_traceback_'\n",
      "\n",
      "During handling of the above exception, another exception occurred:\n",
      "\n",
      "Traceback (most recent call last):\n",
      "  File \"/home/ashutosh/miniconda3/envs/study/lib/python3.7/site-packages/IPython/core/ultratb.py\", line 1101, in get_records\n",
      "    return _fixed_getinnerframes(etb, number_of_lines_of_context, tb_offset)\n",
      "  File \"/home/ashutosh/miniconda3/envs/study/lib/python3.7/site-packages/IPython/core/ultratb.py\", line 248, in wrapped\n",
      "    return f(*args, **kwargs)\n",
      "  File \"/home/ashutosh/miniconda3/envs/study/lib/python3.7/site-packages/IPython/core/ultratb.py\", line 281, in _fixed_getinnerframes\n",
      "    records = fix_frame_records_filenames(inspect.getinnerframes(etb, context))\n",
      "  File \"/home/ashutosh/miniconda3/envs/study/lib/python3.7/inspect.py\", line 1502, in getinnerframes\n",
      "    frameinfo = (tb.tb_frame,) + getframeinfo(tb, context)\n",
      "  File \"/home/ashutosh/miniconda3/envs/study/lib/python3.7/inspect.py\", line 1460, in getframeinfo\n",
      "    filename = getsourcefile(frame) or getfile(frame)\n",
      "  File \"/home/ashutosh/miniconda3/envs/study/lib/python3.7/inspect.py\", line 696, in getsourcefile\n",
      "    if getattr(getmodule(object, filename), '__loader__', None) is not None:\n",
      "  File \"/home/ashutosh/miniconda3/envs/study/lib/python3.7/inspect.py\", line 733, in getmodule\n",
      "    if ismodule(module) and hasattr(module, '__file__'):\n",
      "  File \"/home/ashutosh/miniconda3/envs/study/lib/python3.7/site-packages/tensorflow/__init__.py\", line 50, in __getattr__\n",
      "    module = self._load()\n",
      "  File \"/home/ashutosh/miniconda3/envs/study/lib/python3.7/site-packages/tensorflow/__init__.py\", line 44, in _load\n",
      "    module = _importlib.import_module(self.__name__)\n",
      "  File \"/home/ashutosh/miniconda3/envs/study/lib/python3.7/importlib/__init__.py\", line 127, in import_module\n",
      "    return _bootstrap._gcd_import(name[level:], package, level)\n",
      "  File \"<frozen importlib._bootstrap>\", line 1006, in _gcd_import\n",
      "  File \"<frozen importlib._bootstrap>\", line 983, in _find_and_load\n",
      "  File \"<frozen importlib._bootstrap>\", line 965, in _find_and_load_unlocked\n",
      "ModuleNotFoundError: No module named 'tensorflow_core.estimator'\n",
      "Traceback (most recent call last):\n",
      "  File \"/home/ashutosh/miniconda3/envs/study/lib/python3.7/site-packages/IPython/core/interactiveshell.py\", line 3457, in run_code\n",
      "    exec(code_obj, self.user_global_ns, self.user_ns)\n",
      "  File \"/tmp/ipykernel_15621/2869884725.py\", line 4, in <module>\n",
      "    emb = model.fit(A).transform(m)\n",
      "NameError: name 'model' is not defined\n",
      "\n",
      "During handling of the above exception, another exception occurred:\n",
      "\n",
      "Traceback (most recent call last):\n",
      "  File \"/home/ashutosh/miniconda3/envs/study/lib/python3.7/site-packages/IPython/core/interactiveshell.py\", line 2077, in showtraceback\n",
      "    stb = value._render_traceback_()\n",
      "AttributeError: 'NameError' object has no attribute '_render_traceback_'\n",
      "\n",
      "During handling of the above exception, another exception occurred:\n",
      "\n",
      "Traceback (most recent call last):\n",
      "  File \"/home/ashutosh/miniconda3/envs/study/lib/python3.7/site-packages/IPython/core/interactiveshell.py\", line 3377, in run_ast_nodes\n",
      "    if (await self.run_code(code, result,  async_=asy)):\n",
      "  File \"/home/ashutosh/miniconda3/envs/study/lib/python3.7/site-packages/IPython/core/interactiveshell.py\", line 3474, in run_code\n",
      "    self.showtraceback(running_compiled_code=True)\n",
      "  File \"/home/ashutosh/miniconda3/envs/study/lib/python3.7/site-packages/IPython/core/interactiveshell.py\", line 2080, in showtraceback\n",
      "    value, tb, tb_offset=tb_offset)\n",
      "  File \"/home/ashutosh/miniconda3/envs/study/lib/python3.7/site-packages/IPython/core/ultratb.py\", line 1368, in structured_traceback\n",
      "    self, etype, value, tb, tb_offset, number_of_lines_of_context)\n",
      "  File \"/home/ashutosh/miniconda3/envs/study/lib/python3.7/site-packages/IPython/core/ultratb.py\", line 1268, in structured_traceback\n",
      "    self, etype, value, tb, tb_offset, number_of_lines_of_context\n",
      "  File \"/home/ashutosh/miniconda3/envs/study/lib/python3.7/site-packages/IPython/core/ultratb.py\", line 1125, in structured_traceback\n",
      "    tb_offset)\n",
      "  File \"/home/ashutosh/miniconda3/envs/study/lib/python3.7/site-packages/IPython/core/ultratb.py\", line 1082, in format_exception_as_a_whole\n",
      "    last_unique, recursion_repeat = find_recursion(orig_etype, evalue, records)\n",
      "  File \"/home/ashutosh/miniconda3/envs/study/lib/python3.7/site-packages/IPython/core/ultratb.py\", line 382, in find_recursion\n",
      "    return len(records), 0\n",
      "TypeError: object of type 'NoneType' has no len()\n",
      "\n",
      "During handling of the above exception, another exception occurred:\n",
      "\n",
      "Traceback (most recent call last):\n",
      "  File \"/home/ashutosh/miniconda3/envs/study/lib/python3.7/site-packages/IPython/core/interactiveshell.py\", line 2077, in showtraceback\n",
      "    stb = value._render_traceback_()\n",
      "AttributeError: 'TypeError' object has no attribute '_render_traceback_'\n",
      "\n",
      "During handling of the above exception, another exception occurred:\n",
      "\n",
      "Traceback (most recent call last):\n",
      "  File \"/home/ashutosh/miniconda3/envs/study/lib/python3.7/site-packages/IPython/core/interactiveshell.py\", line 2960, in _run_cell\n",
      "    return runner(coro)\n",
      "  File \"/home/ashutosh/miniconda3/envs/study/lib/python3.7/site-packages/IPython/core/async_helpers.py\", line 78, in _pseudo_sync_runner\n",
      "    coro.send(None)\n",
      "  File \"/home/ashutosh/miniconda3/envs/study/lib/python3.7/site-packages/IPython/core/interactiveshell.py\", line 3186, in run_cell_async\n",
      "    interactivity=interactivity, compiler=compiler, result=result)\n",
      "  File \"/home/ashutosh/miniconda3/envs/study/lib/python3.7/site-packages/IPython/core/interactiveshell.py\", line 3396, in run_ast_nodes\n",
      "    self.showtraceback()\n",
      "  File \"/home/ashutosh/miniconda3/envs/study/lib/python3.7/site-packages/IPython/core/interactiveshell.py\", line 2080, in showtraceback\n",
      "    value, tb, tb_offset=tb_offset)\n",
      "  File \"/home/ashutosh/miniconda3/envs/study/lib/python3.7/site-packages/IPython/core/ultratb.py\", line 1368, in structured_traceback\n",
      "    self, etype, value, tb, tb_offset, number_of_lines_of_context)\n",
      "  File \"/home/ashutosh/miniconda3/envs/study/lib/python3.7/site-packages/IPython/core/ultratb.py\", line 1268, in structured_traceback\n",
      "    self, etype, value, tb, tb_offset, number_of_lines_of_context\n",
      "  File \"/home/ashutosh/miniconda3/envs/study/lib/python3.7/site-packages/IPython/core/ultratb.py\", line 1143, in structured_traceback\n",
      "    chained_exceptions_tb_offset)\n",
      "  File \"/home/ashutosh/miniconda3/envs/study/lib/python3.7/site-packages/IPython/core/ultratb.py\", line 1082, in format_exception_as_a_whole\n",
      "    last_unique, recursion_repeat = find_recursion(orig_etype, evalue, records)\n",
      "  File \"/home/ashutosh/miniconda3/envs/study/lib/python3.7/site-packages/IPython/core/ultratb.py\", line 382, in find_recursion\n",
      "    return len(records), 0\n",
      "TypeError: object of type 'NoneType' has no len()\n",
      "\n",
      "During handling of the above exception, another exception occurred:\n",
      "\n",
      "Traceback (most recent call last):\n",
      "  File \"/home/ashutosh/miniconda3/envs/study/lib/python3.7/site-packages/IPython/core/interactiveshell.py\", line 2077, in showtraceback\n",
      "    stb = value._render_traceback_()\n",
      "AttributeError: 'TypeError' object has no attribute '_render_traceback_'\n",
      "\n",
      "During handling of the above exception, another exception occurred:\n",
      "\n",
      "Traceback (most recent call last):\n",
      "  File \"/home/ashutosh/miniconda3/envs/study/lib/python3.7/site-packages/IPython/core/ultratb.py\", line 1101, in get_records\n",
      "    return _fixed_getinnerframes(etb, number_of_lines_of_context, tb_offset)\n",
      "  File \"/home/ashutosh/miniconda3/envs/study/lib/python3.7/site-packages/IPython/core/ultratb.py\", line 248, in wrapped\n",
      "    return f(*args, **kwargs)\n",
      "  File \"/home/ashutosh/miniconda3/envs/study/lib/python3.7/site-packages/IPython/core/ultratb.py\", line 281, in _fixed_getinnerframes\n",
      "    records = fix_frame_records_filenames(inspect.getinnerframes(etb, context))\n",
      "  File \"/home/ashutosh/miniconda3/envs/study/lib/python3.7/inspect.py\", line 1502, in getinnerframes\n",
      "    frameinfo = (tb.tb_frame,) + getframeinfo(tb, context)\n",
      "  File \"/home/ashutosh/miniconda3/envs/study/lib/python3.7/inspect.py\", line 1460, in getframeinfo\n",
      "    filename = getsourcefile(frame) or getfile(frame)\n",
      "  File \"/home/ashutosh/miniconda3/envs/study/lib/python3.7/inspect.py\", line 696, in getsourcefile\n",
      "    if getattr(getmodule(object, filename), '__loader__', None) is not None:\n",
      "  File \"/home/ashutosh/miniconda3/envs/study/lib/python3.7/inspect.py\", line 733, in getmodule\n",
      "    if ismodule(module) and hasattr(module, '__file__'):\n",
      "  File \"/home/ashutosh/miniconda3/envs/study/lib/python3.7/site-packages/tensorflow/__init__.py\", line 50, in __getattr__\n",
      "    module = self._load()\n",
      "  File \"/home/ashutosh/miniconda3/envs/study/lib/python3.7/site-packages/tensorflow/__init__.py\", line 44, in _load\n",
      "    module = _importlib.import_module(self.__name__)\n",
      "  File \"/home/ashutosh/miniconda3/envs/study/lib/python3.7/importlib/__init__.py\", line 127, in import_module\n",
      "    return _bootstrap._gcd_import(name[level:], package, level)\n",
      "  File \"<frozen importlib._bootstrap>\", line 1006, in _gcd_import\n",
      "  File \"<frozen importlib._bootstrap>\", line 983, in _find_and_load\n",
      "  File \"<frozen importlib._bootstrap>\", line 965, in _find_and_load_unlocked\n",
      "ModuleNotFoundError: No module named 'tensorflow_core.estimator'\n"
     ]
    }
   ],
   "source": [
    "embs = {}\n",
    "from residual2vec.word2vec import Word2Vec\n",
    "for k, model in models.items():\n",
    "# needs to take weighted adjacency amtrix and then pass torch model and the negative sampling to residual2vec_sgd\n",
    "    m = Word2Vec(vocab_size=A.shape[0] + 1, embedding_size=dim, padding_idx=A.shape[0])\n",
    "    embs[k] = model.fit(A).transform(m)"
   ]
  },
  {
   "cell_type": "code",
   "execution_count": null,
   "metadata": {},
   "outputs": [],
   "source": []
  }
 ],
 "metadata": {
  "kernelspec": {
   "display_name": "Python 3 (ipykernel)",
   "language": "python",
   "name": "python3"
  },
  "language_info": {
   "codemirror_mode": {
    "name": "ipython",
    "version": 3
   },
   "file_extension": ".py",
   "mimetype": "text/x-python",
   "name": "python",
   "nbconvert_exporter": "python",
   "pygments_lexer": "ipython3",
   "version": "3.7.12"
  }
 },
 "nbformat": 4,
 "nbformat_minor": 1
}
